{"uuid": "57f920a2-8596-4dd3-b0ba-4f813bf4ae15", "children": ["04baa469-e701-4625-8296-072d4f15d25b", "5f91df9b-496d-447c-9898-e7c2bac2421a"], "befores": [{"name": "beforeClass", "status": "broken", "statusDetails": {"message": "selenium.common.exceptions.WebDriverException: Message: An unknown server-side error occurred while processing the command. Original error: Error finding if 'io.appium.uiautomator2.server.test' is installed. Original error: Error executing adbExec. Original error: 'Command 'C:\\\\Users\\\\a.padlo\\\\AppData\\\\Local\\\\Android\\\\Sdk\\\\platform-tools\\\\adb.exe -P 5037 -s R5CN60FN18E shell dumpsys package io.appium.uiautomator2.server.test' exited with code 1'; Stderr: 'adb.exe: device 'R5CN60FN18E' not found'; Code: '1'\n\n", "trace": "  File \"c:\\users\\a.padlo\\appdata\\local\\programs\\python\\python39\\lib\\site-packages\\pluggy\\callers.py\", line 187, in _multicall\n    res = hook_impl.function(*args)\n  File \"c:\\users\\a.padlo\\appdata\\local\\programs\\python\\python39\\lib\\site-packages\\_pytest\\fixtures.py\", line 1126, in pytest_fixture_setup\n    result = call_fixture_func(fixturefunc, request, kwargs)\n  File \"c:\\users\\a.padlo\\appdata\\local\\programs\\python\\python39\\lib\\site-packages\\_pytest\\fixtures.py\", line 925, in call_fixture_func\n    fixture_result = next(generator)\n  File \"D:\\Python\\Automation\\AppiumFramework\\tests\\conftest.py\", line 10, in beforeClass\n    driver = driver1.getDriverMethod()\n  File \"D:\\Python\\Automation\\AppiumFramework\\base\\DriverClass.py\", line 18, in getDriverMethod\n    driver = webdriver.Remote(\"http://127.0.0.1:4723/wd/hub\", desired_caps)\n  File \"c:\\users\\a.padlo\\appdata\\local\\programs\\python\\python39\\lib\\site-packages\\appium\\webdriver\\webdriver.py\", line 151, in __init__\n    super().__init__(\n  File \"C:\\Users\\a.padlo\\AppData\\Roaming\\Python\\Python39\\site-packages\\selenium\\webdriver\\remote\\webdriver.py\", line 157, in __init__\n    self.start_session(capabilities, browser_profile)\n  File \"c:\\users\\a.padlo\\appdata\\local\\programs\\python\\python39\\lib\\site-packages\\appium\\webdriver\\webdriver.py\", line 225, in start_session\n    response = self.execute(RemoteCommand.NEW_SESSION, parameters)\n  File \"C:\\Users\\a.padlo\\AppData\\Roaming\\Python\\Python39\\site-packages\\selenium\\webdriver\\remote\\webdriver.py\", line 321, in execute\n    self.error_handler.check_response(response)\n  File \"C:\\Users\\a.padlo\\AppData\\Roaming\\Python\\Python39\\site-packages\\selenium\\webdriver\\remote\\errorhandler.py\", line 242, in check_response\n    raise exception_class(message, screen, stacktrace)\n"}, "start": 1644171435254, "stop": 1644171450768}], "start": 1644171435254, "stop": 1644171450923}