{"uuid": "8864d83f-583a-4d90-a06d-3c3ceb1c505e", "children": ["5730e5bf-fef5-40de-bcc5-d5024000a377", "ecb4dea2-66fb-46da-bb69-aca529b8b2f7"], "befores": [{"name": "beforeClass", "status": "broken", "statusDetails": {"message": "selenium.common.exceptions.WebDriverException: Message: An unknown server-side error occurred while processing the command. Original error: Cannot start the 'com.skill2lead.appiumdemo' application. Visit https://github.com/appium/appium/blob/master/docs/en/writing-running-appium/android/activity-startup.md for troubleshooting. Original error: Error executing adbExec. Original error: 'Command 'C:\\\\Users\\\\a.padlo\\\\AppData\\\\Local\\\\Android\\\\Sdk\\\\platform-tools\\\\adb.exe -P 5037 -s R5CN60FN18E shell am start -W -n com.skill2lead.appiumdemo/com.skill2lead.appiumdemo.MainActivity -S -a android.intent.action.MAIN -c android.intent.category.LAUNCHER -f 0x10200000' exited with code 1'; Stderr: 'adb.exe: device 'R5CN60FN18E' not found'; Code: '1'\n\n", "trace": "  File \"c:\\users\\a.padlo\\appdata\\local\\programs\\python\\python39\\lib\\site-packages\\pluggy\\callers.py\", line 187, in _multicall\n    res = hook_impl.function(*args)\n  File \"c:\\users\\a.padlo\\appdata\\local\\programs\\python\\python39\\lib\\site-packages\\_pytest\\fixtures.py\", line 1126, in pytest_fixture_setup\n    result = call_fixture_func(fixturefunc, request, kwargs)\n  File \"c:\\users\\a.padlo\\appdata\\local\\programs\\python\\python39\\lib\\site-packages\\_pytest\\fixtures.py\", line 925, in call_fixture_func\n    fixture_result = next(generator)\n  File \"D:\\Python\\Automation\\AppiumFramework\\tests\\conftest.py\", line 10, in beforeClass\n    driver = driver1.getDriverMethod()\n  File \"D:\\Python\\Automation\\AppiumFramework\\base\\DriverClass.py\", line 18, in getDriverMethod\n    driver = webdriver.Remote(\"http://127.0.0.1:4723/wd/hub\", desired_caps)\n  File \"c:\\users\\a.padlo\\appdata\\local\\programs\\python\\python39\\lib\\site-packages\\appium\\webdriver\\webdriver.py\", line 151, in __init__\n    super().__init__(\n  File \"C:\\Users\\a.padlo\\AppData\\Roaming\\Python\\Python39\\site-packages\\selenium\\webdriver\\remote\\webdriver.py\", line 157, in __init__\n    self.start_session(capabilities, browser_profile)\n  File \"c:\\users\\a.padlo\\appdata\\local\\programs\\python\\python39\\lib\\site-packages\\appium\\webdriver\\webdriver.py\", line 225, in start_session\n    response = self.execute(RemoteCommand.NEW_SESSION, parameters)\n  File \"C:\\Users\\a.padlo\\AppData\\Roaming\\Python\\Python39\\site-packages\\selenium\\webdriver\\remote\\webdriver.py\", line 321, in execute\n    self.error_handler.check_response(response)\n  File \"C:\\Users\\a.padlo\\AppData\\Roaming\\Python\\Python39\\site-packages\\selenium\\webdriver\\remote\\errorhandler.py\", line 242, in check_response\n    raise exception_class(message, screen, stacktrace)\n"}, "start": 1644154355060, "stop": 1644154376854}], "start": 1644154355060, "stop": 1644154377015}